Workbook

Sheet Honor Pledge
A1: On my honor, I, Josh Cha,have neither given nor received unauthorized aid in doing this assignment.

Sheet Class Budget Data
A1: Home (Rent rent insurance etc) | B1: Cell phone | C1: Cable or Internet | D1: Car - Monthly payment | E1: Car - Gasoline | F1: Other Transportation (bus etc) | G1: Groceries (e.g. Walmart) | H1: Restaurants / fast food/ coffee shops | I1: Daycare/kids | J1: Clothing | K1: School supplies | L1: Fun stuff (parties movies hobbies etc) | M1: Savings for unexpected expenses | N1: Savings for Retirement (e.g savings to ROTH IRA account) | O1: Subscriptions (Apple music Amazon music Netflix Disney + etc) | P1: Travel | Q1: Payments to loans | R1: What is your monthly income? - /month
A2: 900 | B2: 30 | C2: 50 | D2: 400 | E2: 50 | F2: 25 | G2: 120 | H2: 300 | I2: 500 | J2: 50 | K2: 20 | L2: 50 | M2: 1000 | N2: 500 | O2: 45 | P2: 200 | Q2: 500 | R2: 3000
A3: 583 | B3: 50 | C3: 40 | D3: 375 | E3: 125 | F3: 50 | G3: 200 | H3: 50 | J3: 75 | K3: 20 | L3: 200 | M3: 100 | N3: 100 | O3: 20 | P3: 40 | Q3: 200 | R3: 700
A4: 1100 | B4: 30 | C4: 50 | D4: 400 | E4: 131.76 | F4: 40 | G4: 70 | H4: 200 | J4: 50 | K4: 30 | L4: 80 | M4: 100 | N4: 100 | O4: 10 | P4: 300 | Q4: 50 | R4: 700
A5: 900 | B5: 40 | C5: 50 | D5: 750 | E5: 100 | F5: 50 | G5: 240 | H5: 250 | J5: 70 | K5: 50 | L5: 50 | M5: 150 | N5: 500 | O5: 100 | P5: 100 | Q5: 200 | R5: 60
A6: 1200 | B6: 40 | C6: 20 | D6: 2000 | E6: 100 | F6: 50 | G6: 200 | H6: 200 | J6: 10 | K6: 40 | L6: 30 | M6: 300 | N6: 300 | O6: 40 | P6: 25 | Q6: 200 | R6: 50
A7: 1200 | B7: 75 | C7: 10 | D7: 100 | E7: 10 | F7: 1200 | G7: 200 | H7: 250 | J7: 50 | K7: 15 | L7: 50 | M7: 200 | N7: 100 | O7: 15 | P7: 200 | Q7: 50 | R7: 4000
A8: 583 | B8: 150 | C8: 100 | D8: 700 | E8: 60 | F8: 60 | G8: 600 | H8: 250 | J8: 50 | K8: 20 | L8: 25 | M8: 100 | N8: 200 | O8: 6 | P8: 10 | Q8: 200 | R8: 2700
A9: 1600 | B9: 120 | C9: 20 | D9: 170 | E9: 40 | F9: 10 | G9: 150 | H9: 600 | J9: 20 | K9: 10 | L9: 50 | M9: 100 | N9: 10 | O9: 138 | P9: 100 | Q9: 60 | R9: 1600
A10: 1000 | B10: 40 | C10: 75 | D10: 2000 | E10: 45 | F10: 100 | G10: 300 | H10: 300 | J10: 200 | K10: 10 | L10: 20 | M10: 500 | N10: 100 | O10: 5 | P10: 100 | Q10: 50 | R10: 1000
A11: 900 | B11: 85 | C11: 10 | D11: 200 | E11: 10 | F11: 30 | G11: 400 | H11: 50 | J11: 50 | K11: 120 | L11: 50 | M11: 100 | N11: 100 | O11: 7 | P11: 150 | Q11: 63 | R11: 1000
A12: 2000 | B12: 120 | C12: 30 | D12: 250 | E12: 60 | F12: 5 | G12: 300 | H12: 100 | J12: 100 | K12: 10 | L12: 50 | M12: 10 | N12: 400 | O12: 15 | P12: 1000 | Q12: 1500 | R12: 1000
A13: 1100 | B13: 65 | C13: 12.5 | D13: 2000 | E13: 120 | F13: 50 | G13: 50 | H13: 250 | J13: 50 | K13: 10 | L13: 50 | M13: 100 | N13: 100 | O13: 50 | P13: 50 | Q13: 500 | R13: 80000
A14: 850 | B14: 50 | C14: 80 | D14: 400 | E14: 180 | F14: 50 | G14: 50 | H14: 100 | J14: 50 | K14: 20 | L14: 250 | M14: 400 | N14: 80 | O14: 150 | P14: 100 | R14: 80000
A15: 850 | B15: 25 | C15: 50 | D15: 60 | E15: 40 | F15: 20 | G15: 400 | H15: 75 | J15: 25 | K15: 100 | L15: 80 | M15: 20 | N15: 100 | O15: 50 | P15: 300 | R15: 70000
A16: 1300 | B16: 100 | C16: 10 | D16: 500 | E16: 100 | F16: 15 | G16: 90 | H16: 50 | J16: 30 | K16: 6.25 | L16: 50 | M16: 350 | N16: 100 | O16: 6.6 | P16: 15 | R16: 48000
A17: 537 | B17: 30 | C17: 40 | D17: 250 | E17: 100 | F17: 35 | G17: 50 | H17: 20 | J17: 150 | K17: 2 | L17: 1000 | M17: 15 | N17: 200 | O17: 10 | P17: 100 | R17: 35000
A18: 970 | B18: 50 | C18: 150 | D18: 100 | E18: 100 | F18: 80 | G18: 85 | H18: 400 | J18: 30 | K18: 10 | L18: 50 | M18: 40 | N18: 100 | O18: 150 | P18: 230 | R18: 25000
A19: 600 | B19: 55 | C19: 30 | D19: 615 | E19: 75 | F19: 100 | G19: 20 | H19: 120 | J19: 100 | K19: 40 | L19: 300 | M19: 100 | N19: 100 | O19: 150 | P19: 100 | R19: 15000
A20: 650 | B20: 30 | C20: 50 | D20: 357 | E20: 40 | F20: 100 | G20: 100 | H20: 300 | J20: 150 | K20: 30 | L20: 60 | M20: 400 | N20: 10 | O20: 15 | P20: 25 | R20: 10000
A21: 1000 | B21: 25 | C21: 100 | D21: 400 | E21: 40 | F21: 16 | G21: 100 | H21: 40 | J21: 50 | K21: 50 | L21: 400 | M21: 5 | N21: 80 | O21: 20 | P21: 40 | R21: 10000
A22: 700 | B22: 25 | C22: 20 | D22: 200 | E22: 60 | F22: 33 | G22: 250 | H22: 50 | J22: 100 | K22: 20 | L22: 150 | M22: 100 | N22: 200 | O22: 50 | P22: 42 | R22: 10000
A23: 800 | B23: 200 | C23: 50 | D23: 300 | E23: 30 | F23: 20 | G23: 200 | H23: 50 | J23: 70 | K23: 37.5 | L23: 500 | M23: 100 | N23: 200 | O23: 20 | P23: 300 | R23: 9000
A24: 1100 | B24: 80 | C24: 40 | D24: 500 | E24: 58 | F24: 100 | G24: 400 | H24: 1000 | J24: 50 | K24: 10 | L24: 35 | M24: 200 | N24: 500 | O24: 10 | P24: 30 | R24: 9000
A25: 1100 | B25: 40 | C25: 70 | D25: 200 | E25: 35 | F25: 100 | G25: 240 | H25: 150 | J25: 15 | K25: 15 | L25: 100 | M25: 500 | N25: 200 | O25: 20 | P25: 200 | R25: 7000
... A111: 850 | B111: 100 | C111: 30 | D111: 145 | E111: 45 | F111: 100 | G111: 200 | H111: 300 | J111: 50 | K111: 20 | L111: 50 | M111: 100 | N111: 1000 | O111: 100 | P111: 400 | R111: 1400
A112: 300 | B112: 100 | C112: 35 | E112: 80 | G112: 100 | H112: 500 | J112: 200 | K112: 20 | L112: 50 | M112: 10 | N112: 50 | O112: 20 | P112: 600 | R112: 1300
A113: 1100 | B113: 10 | C113: 30 | E113: 75 | G113: 180 | H113: 60 | J113: 50 | K113: 25 | L113: 45 | M113: 2000 | N113: 100 | O113: 20 | P113: 900 | R113: 1300
A114: 1000 | B114: 200 | C114: 20 | E114: 150 | G114: 100 | H114: 170 | J114: 50 | K114: 30 | L114: 20 | M114: 40 | N114: 10 | O114: 25 | P114: 120 | R114: 1300
A115: 725 | B115: 50 | C115: 25 | E115: 90 | G115: 250 | H115: 30 | J115: 20 | K115: 10 | L115: 40 | M115: 50 | N115: 200 | O115: 25 | P115: 100 | R115: 1300
A116: 711 | B116: 50 | C116: 20 | E116: 120 | G116: 256 | H116: 600 | J116: 30 | K116: 20 | L116: 200 | M116: 50 | N116: 200 | O116: 30 | P116: 100 | R116: 1300
A117: 800 | B117: 80 | C117: 35 | E117: 60 | G117: 130 | H117: 100 | J117: 50 | K117: 30 | L117: 50 | M117: 291 | N117: 500 | O117: 15 | P117: 100 | R117: 1300
A118: 1080 | B118: 20 | C118: 100 | E118: 120 | G118: 150 | H118: 100 | J118: 20 | K118: 50 | L118: 10 | M118: 160 | N118: 50 | O118: 500 | P118: 100 | R118: 1300
A119: 1000 | B119: 50 | C119: 50 | E119: 30 | G119: 300 | H119: 25 | J119: 200 | K119: 10 | L119: 50 | M119: 100 | N119: 300 | O119: 100 | P119: 80 | R119: 1200
A120: 1400 | B120: 8 | C120: 50 | E120: 75 | G120: 1200 | H120: 50 | J120: 50 | K120: 20 | L120: 200 | M120: 80 | N120: 100 | O120: 60 | P120: 50 | R120: 1200
A121: 900 | B121: 45 | C121: 50 | E121: 80 | G121: 100 | H121: 30 | J121: 5 | K121: 10 | L121: 50 | M121: 50 | N121: 25 | O121: 55 | P121: 50 | R121: 1200
A122: 1000 | B122: 19 | C122: 50 | E122: 80 | G122: 100 | H122: 200 | J122: 300 | K122: 10 | L122: 200 | M122: 100 | N122: 50 | O122: 30 | P122: 25 | R122: 1200
A123: 70 | B123: 62 | C123: 10 | E123: 150 | G123: 300 | H123: 3000 | J123: 20 | K123: 50 | L123: 50 | M123: 1000 | N123: 200 | O123: 10 | P123: 100 | R123: 1200
A124: 750 | B124: 50 | C124: 50 | E124: 100 | G124: 300 | H124: 200 | J124: 200 | K124: 10 | L124: 50 | M124: 50 | N124: 45 | O124: 20 | P124: 1200 | R124: 1100
A125: 725 | B125: 100 | C125: 30 | E125: 150 | G125: 200 | H125: 200 | J125: 30 | K125: 20 | L125: 30 | M125: 500 | O125: 20 | P125: 200 | R125: 1100
...

Sheet Monthly Expenses
A1: In this worksheet, you will compare the expenses of the class (according to your ID assignment), with your personal expenses
B3: Class expenses | C3: =SUM(B8:B24) -> 4664.2849
B4: My expenses | C4: =SUM(C8:C24) -> 1775
B5: Difference | C5: =C3-C4 -> 2889.2849
A7: Gainesville: Monthly Expenses | B7: Class expenses | C7: My Expenses | E7: My monthly expenses ordered from Largest to smallest
A8: Home (Rent rent insurance etc) | B8: =AVERAGE('Class Budget Data'!A:A) -> 1022.6546 | C8: 850 | E8: Item | F8: My expenses | H8: Item | I8: My expenses
A9: Cell phone | B9: =AVERAGE('Class Budget Data'!B:B) -> 67.928856 | C9: 10 | E9: Cable or Internet | F9: 0 | H9: Car | I9: 0 | K9: Using the VLookUp function
A10: Cable or Internet | B10: =AVERAGE('Class Budget Data'!C:C) -> 55.688616 | C10: 0 | E10: Car - Monthly payment | F10: 0 | H10: Clothing | I10: 50 | K10: Type below an expense item to find the value
A11: Car - Monthly payment | B11: =AVERAGE('Class Budget Data'!D:D) -> 514.917 | C11: 0 | E11: Other Transportation (bus etc) | F11: 0 | H11: Fun | I11: 100 | K11: Travel | L11: =VLOOKUP(K11,H9:I25,2,FALSE) -> 300
A12: Car - Gasoline | B12: =AVERAGE('Class Budget Data'!E:E) -> 101.03331 | C12: 100 | E12: Daycare/kids | F12: 0 | H12: Gas | I12: 100
A13: Other Transportation (bus etc) | B13: =AVERAGE('Class Budget Data'!F:F) -> 68.022727 | C13: 0 | E13: School supplies | F13: 0 | H13: Groceries | I13: 100
A14: Groceries (e.g. Walmart) | B14: =AVERAGE('Class Budget Data'!G:G) -> 209.8019 | C14: 100 | E14: Savings for unexpected expenses | F14: 0 | H14: Home | I14: 850
A15: Restaurants / fast food/ coffee shops | B15: =AVERAGE('Class Budget Data'!H:H) -> 180.14286 | C15: 250 | E15: Savings for Retirement (e.g savings to ROTH IRA account) | F15: 0 | H15: Internet | I15: 0
A16: Daycare/kids | B16: =AVERAGE('Class Budget Data'!I:I) -> 500 | C16: 0 | E16: Payments to loans | F16: 0 | H16: Kids | I16: 0
A17: Clothing | B17: =AVERAGE('Class Budget Data'!J:J) -> 91.130699 | C17: 50 | E17: Cell phone | F17: 10 | H17: Loans | I17: 0
A18: School supplies | B18: =AVERAGE('Class Budget Data'!K:K) -> 34.674831 | C18: 0 | E18: Subscriptions (Apple music Amazon music Netflix Disney + etc) | F18: 15 | H18: Other | I18: 0
A19: Fun stuff (parties movies hobbies etc) | B19: =AVERAGE('Class Budget Data'!L:L) -> 137.37143 | C19: 100 | E19: Clothing | F19: 50 | H19: Phone | I19: 10
A20: Savings for unexpected expenses | B20: =AVERAGE('Class Budget Data'!M:M) -> 367.22917 | C20: 0 | E20: Car - Gasoline | F20: 100 | H20: Restaurants | I20: 250
A21: Savings for Retirement (e.g savings to ROTH IRA account) | B21: =AVERAGE('Class Budget Data'!N:N) -> 800.83171 | C21: 0 | E21: Groceries (e.g. Walmart) | F21: 100 | H21: Retirement | I21: 0
A22: Subscriptions (Apple music Amazon music Netflix Disney + etc) | B22: =AVERAGE('Class Budget Data'!O:O) -> 52.663438 | C22: 15 | E22: Fun stuff (parties movies hobbies etc) | F22: 100 | H22: Emergency | I22: 0
A23: Travel | B23: =AVERAGE('Class Budget Data'!P:P) -> 162.44385 | C23: 300 | E23: Restaurants / fast food/ coffee shops | F23: 250 | H23: School | I23: 0
A24: Payments to loans | B24: =AVERAGE('Class Budget Data'!Q:Q) -> 297.75 | C24: 0 | E24: Travel | F24: 300 | H24: Subscriptions | I24: 15
E25: Home (Rent rent insurance etc) | F25: 850 | H25: Travel | I25: 300

Sheet Charts
A1: 3D - Column chart comparison of class expenses vs my expenses | I1: Pie chart of monthly expenses
